[2024-12-08 23:00:02,327][src.utils.utils][INFO] - [rank: 0] Enforcing tags! <cfg.extras.enforce_tags=True>
[2024-12-08 23:00:02,329][src.utils.utils][INFO] - [rank: 0] Printing config tree with Rich! <cfg.extras.print_config=True>
[2024-12-08 23:00:02,354][__main__][INFO] - [rank: 0] Instantiating datamodule <src.data.ImageCaptionDataModule>
[2024-12-08 23:00:02,621][__main__][INFO] - [rank: 0] Instantiating model <src.models.ImageCaptionModule>
[2024-12-08 23:00:02,624][src.utils.utils][ERROR] - [rank: 0] 
Traceback (most recent call last):
  File "/Library/Frameworks/Python.framework/Versions/3.11/lib/python3.11/site-packages/hydra/_internal/utils.py", line 644, in _locate
    obj = getattr(obj, part)
          ^^^^^^^^^^^^^^^^^^
AttributeError: module 'src.models' has no attribute 'ImageCaptionModule'

During handling of the above exception, another exception occurred:

Traceback (most recent call last):
  File "/Library/Frameworks/Python.framework/Versions/3.11/lib/python3.11/site-packages/hydra/_internal/utils.py", line 650, in _locate
    obj = import_module(mod)
          ^^^^^^^^^^^^^^^^^^
  File "/Library/Frameworks/Python.framework/Versions/3.11/lib/python3.11/importlib/__init__.py", line 126, in import_module
    return _bootstrap._gcd_import(name[level:], package, level)
           ^^^^^^^^^^^^^^^^^^^^^^^^^^^^^^^^^^^^^^^^^^^^^^^^^^^^
  File "<frozen importlib._bootstrap>", line 1204, in _gcd_import
  File "<frozen importlib._bootstrap>", line 1176, in _find_and_load
  File "<frozen importlib._bootstrap>", line 1140, in _find_and_load_unlocked
ModuleNotFoundError: No module named 'src.models.ImageCaptionModule'

The above exception was the direct cause of the following exception:

Traceback (most recent call last):
  File "/Library/Frameworks/Python.framework/Versions/3.11/lib/python3.11/site-packages/hydra/_internal/instantiate/_instantiate2.py", line 134, in _resolve_target
    target = _locate(target)
             ^^^^^^^^^^^^^^^
  File "/Library/Frameworks/Python.framework/Versions/3.11/lib/python3.11/site-packages/hydra/_internal/utils.py", line 653, in _locate
    raise ImportError(
ImportError: Error loading 'src.models.ImageCaptionModule':
ModuleNotFoundError("No module named 'src.models.ImageCaptionModule'")
Are you sure that 'ImageCaptionModule' is importable from module 'src.models'?

The above exception was the direct cause of the following exception:

Traceback (most recent call last):
  File "/Users/phulocnguyen/Documents/Workspace/ImageCaptioning/src/utils/utils.py", line 68, in wrap
    metric_dict, object_dict = task_func(cfg=cfg)
                               ^^^^^^^^^^^^^^^^^^
  File "/Users/phulocnguyen/Documents/Workspace/ImageCaptioning/src/train.py", line 61, in train
    model: LightningModule = hydra.utils.instantiate(cfg.model)
                             ^^^^^^^^^^^^^^^^^^^^^^^^^^^^^^^^^^
  File "/Library/Frameworks/Python.framework/Versions/3.11/lib/python3.11/site-packages/hydra/_internal/instantiate/_instantiate2.py", line 226, in instantiate
    return instantiate_node(
           ^^^^^^^^^^^^^^^^^
  File "/Library/Frameworks/Python.framework/Versions/3.11/lib/python3.11/site-packages/hydra/_internal/instantiate/_instantiate2.py", line 333, in instantiate_node
    _target_ = _resolve_target(node.get(_Keys.TARGET), full_key)
               ^^^^^^^^^^^^^^^^^^^^^^^^^^^^^^^^^^^^^^^^^^^^^^^^^
  File "/Library/Frameworks/Python.framework/Versions/3.11/lib/python3.11/site-packages/hydra/_internal/instantiate/_instantiate2.py", line 139, in _resolve_target
    raise InstantiationException(msg) from e
hydra.errors.InstantiationException: Error locating target 'src.models.ImageCaptionModule', set env var HYDRA_FULL_ERROR=1 to see chained exception.
full_key: model
[2024-12-08 23:00:02,625][src.utils.utils][INFO] - [rank: 0] Output dir: /Users/phulocnguyen/Documents/Workspace/ImageCaptioning/logs/train/runs/2024-12-08_23-00-02
